Workbook

Sheet Pivot Inquinanti
A1: Inquinante | B1: PM10
A3: Etichette di riga | B3: Media di Valore
A4: 2025 | B4: 37.732609
A5: Trim4 | B5: 37.732609
A6: ott | B6: 36.077419
A7: 45931 | B7: 14.2
A8: 45932 | B8: 20.5
A9: 45933 | B9: 36.2
A10: 45934 | B10: 46.7
A11: 45935 | B11: 14.3
A12: 45936 | B12: 16.9
A13: 45937 | B13: 34.7
A14: 45938 | B14: 53.7
A15: 45939 | B15: 72.3
A16: 45940 | B16: 69.8
A17: 45941 | B17: 69.8
A18: 45942 | B18: 61.8
... A37: 45961 | B37: 18.3
A38: nov | B38: 38.143333
A39: 45962 | B39: 26.7
A40: 45963 | B40: 28.4
A41: 45964 | B41: 15.6
A42: 45965 | B42: 30.1
A43: 45966 | B43: 40.4
A44: 45967 | B44: 47.4
A45: 45968 | B45: 44.2
A46: 45969 | B46: 45
A47: 45970 | B47: 58
A48: 45971 | B48: 55.5
A49: 45972 | B49: 52.9
A50: 45973 | B50: 43.8
... A68: 45991 | B68: 55.5
A69: dic | B69: 38.990323
A70: 45992 | B70: 39.8
A71: 45993 | B71: 48.1
A72: 45994 | B72: 58.4
A73: 45995 | B73: 37.1
A74: 45996 | B74: 27.3
A75: 45997 | B75: 38.3
A76: 45998 | B76: 43.7
...

Sheet Dati
A1: IdSensore | B1: Data | C1: Inquinante | D1: Valore | E1: idOperatore
A2: 117165 | B2: 45931 | C2: =VLOOKUP(A2,'Anagrafica sensori'!$A$2:$B$9,2,FALSE) -> PM10 | D2: 14.2 | E2: 1
A3: 117164 | B3: 45931 | C3: =VLOOKUP(A3,'Anagrafica sensori'!$A$2:$B$9,2,FALSE) -> Ozono | D3: 51.6 | E3: 11
A4: 117164 | B4: 45931 | C4: =VLOOKUP(A4,'Anagrafica sensori'!$A$2:$B$9,2,FALSE) -> Ozono | D4: 57.4 | E4: 12
A5: 117163 | B5: 45931 | C5: =VLOOKUP(A5,'Anagrafica sensori'!$A$2:$B$9,2,FALSE) -> Biossido di Azoto | D5: 23.5 | E5: 1
A6: 117163 | B6: 45931 | C6: =VLOOKUP(A6,'Anagrafica sensori'!$A$2:$B$9,2,FALSE) -> Biossido di Azoto | D6: 38.3 | E6: 12
A7: 120726 | B7: 45931 | C7: =VLOOKUP(A7,'Anagrafica sensori'!$A$2:$B$9,2,FALSE) -> Particelle sospese PM2.5 | D7: 9.1 | E7: 1
A8: 117165 | B8: 45932 | C8: =VLOOKUP(A8,'Anagrafica sensori'!$A$2:$B$9,2,FALSE) -> PM10 | D8: 20.5 | E8: 1
A9: 117164 | B9: 45932 | C9: =VLOOKUP(A9,'Anagrafica sensori'!$A$2:$B$9,2,FALSE) -> Ozono | D9: 54.8 | E9: 11
A10: 117163 | B10: 45932 | C10: =VLOOKUP(A10,'Anagrafica sensori'!$A$2:$B$9,2,FALSE) -> Biossido di Azoto | D10: 37.2 | E10: 1
A11: 117163 | B11: 45932 | C11: =VLOOKUP(A11,'Anagrafica sensori'!$A$2:$B$9,2,FALSE) -> Biossido di Azoto | D11: 67.1 | E11: 12
A12: 117164 | B12: 45932 | C12: =VLOOKUP(A12,'Anagrafica sensori'!$A$2:$B$9,2,FALSE) -> Ozono | D12: 63 | E12: 12
A13: 120726 | B13: 45932 | C13: =VLOOKUP(A13,'Anagrafica sensori'!$A$2:$B$9,2,FALSE) -> Particelle sospese PM2.5 | D13: 10.3 | E13: 1
... A1225: 120726 | B1225: 46134 | C1225: =VLOOKUP(A1225,'Anagrafica sensori'!$A$2:$B$9,2,FALSE) -> Particelle sospese PM2.5 | D1225: 7.8 | E1225: 1

Sheet Anagrafica sensori
A1: IdSensore | B1: NomeTipoSensore | C1: UnitaMisura | D1: Idstazione | E1: Sensore | F1: Provincia | G1: Comune
A2: 101396 | B2: Biossido di Azoto | C2: µg/m³ | D2: 100422 | E2: NO2 Cormano | F2: MI | G2: Cormano
A3: 101397 | B3: Ozono | C3: µg/m³ | D3: 100422 | E3: O3 Cormano | F3: MI | G3: Cormano
A4: 101398 | B4: PM10 | C4: µg/m³ | D4: 100422 | E4: PM10 Cormano | F4: MI | G4: Cormano
A5: 105426 | B5: Particelle sospese PM2.5 | C5: µg/m³ | D5: 100422 | E5: PM2.5 Cormano | F5: MI | G5: Cormano
A6: 117163 | B6: Biossido di Azoto | C6: µg/m³ | D6: 100422 | E6: NO2 Urbanizzato Cormano | F6: MI | G6: Cormano
A7: 117164 | B7: Ozono | C7: µg/m³ | D7: 100422 | E7: O3 Urbanizzato Cormano | F7: MI | G7: Cormano
A8: 117165 | B8: PM10 | C8: µg/m³ | D8: 100422 | E8: PM10 Urbanizzato Cormano | F8: MI | G8: Cormano
A9: 120726 | B9: Particelle sospese PM2.5 | C9: µg/m³ | D9: 100422 | E9: PM2.5 Urbanizzato Cormano | F9: MI | G9: Cormano
